try {
    const a = 15;
    console.log(a);
} catch (e) {
    console.log("Error comes")
} finally {
    console.log("Program done")
}

